<!doctype html>
<html>
  <head>
    <title>Suspense test</title>
    <meta charset="utf-8" />
    <link rel="icon" href="data:," />
  </head>

  <body>
    <div id="app"></div>
    <script type="module" jsenv-type="module/jsx">
      /* eslint-disable no-unused-vars */
      import { render } from "preact";
      import { Suspense } from "preact/compat";
      import { useState, useRef } from "preact/hooks";
      import { use } from "./use.js";
      import { ErrorBoundary } from "./error_boundary.jsx";

      // A tester maintenant: quid lorsqu'une erreur est throw?

      const App = () => {
        return (
          <div>
            <h1>Suspense Test</h1>
            <Suspense fallback={<div>Loading...</div>}>
              <ChildLoadingFor500Ms />
              <p>Content below Suspense.</p>
            </Suspense>
          </div>
        );
      };

      // Create the second promise OUTSIDE the component to avoid recreating it
      const promiseResolvedAfter500 = new Promise((resolve) => {
        setTimeout(() => {
          resolve("Hook data loaded!");
        }, 500);
      });
      const ChildLoadingFor500Ms = () => {
        const result2 = use(promiseResolvedAfter500);
        return (
          <div>
            <div>Use Hook: {result2}</div>
          </div>
        );
      };
      render(<App />, document.getElementById("app"));
    </script>
  </body>
</html>
