<!--?xml version="1.0" encoding="UTF-8"?-->
<testsuite time="[time]" timestamp="[timestamp]" tests="2" skipped="0" failures="2">
  <testcase file="error_in_timeout.spec.js" name="worker_thread" time="[time]" timestamp="[timestamp]" tests="1" errors="1">
    <properties>
      <property name="runtimeName" value="node_worker_thread"></property>
      <property name="runtimeVersion" value="22.11.0"></property>
    </properties>
  </testcase>
  <error type="Error">1 | await new Promise(() =&gt; {
2 |   setTimeout(() =&gt; {
3 |     throw new Error("here");
              ^
Error: here
  at Timeout._onTimeout (base/node_client/error_in_timeout.spec.js:3:11)</error>
  <testcase file="error_in_timeout.spec.js" name="child_process" time="[time]" timestamp="[timestamp]" tests="1" errors="1">
    <properties>
      <property name="runtimeName" value="node_child_process"></property>
      <property name="runtimeVersion" value="22.11.0"></property>
    </properties>
  </testcase>
  <error type="Error">1 | await new Promise(() =&gt; {
2 |   setTimeout(() =&gt; {
3 |     throw new Error("here");
              ^
Error: here
  at Timeout._onTimeout (base/node_client/error_in_timeout.spec.js:3:11)</error>
</testsuite>