<!--?xml version="1.0" encoding="UTF-8"?-->
<testsuite time="[time]" timestamp="[timestamp]" tests="2" skipped="0" failures="2">
  <testcase file="error_in_source_function.spec.js" name="worker_thread" time="[time]" timestamp="[timestamp]" tests="1" errors="1">
    <properties>
      <property name="runtimeName" value="node_worker_thread"></property>
      <property name="runtimeVersion" value="23.11.0"></property>
    </properties>
  </testcase>
  <error type="Error">1 | export const doSomething = () =&gt; {
2 |   throw new Error("something");
            ^
Error: something
  at doSomething (base/node_client/something.js:2:9)
  at base/node_client/error_in_source_function.spec.js:3:1
  at async executeUsingDynamicImport (@jsenv/core/packages/related/test/src/runtime_node/execute_using_dynamic_import.js:71:23)
  at async @jsenv/core/packages/related/test/src/runtime_node/node_worker_thread_controlled.mjs:95:21</error>
  <testcase file="error_in_source_function.spec.js" name="child_process" time="[time]" timestamp="[timestamp]" tests="1" errors="1">
    <properties>
      <property name="runtimeName" value="node_child_process"></property>
      <property name="runtimeVersion" value="23.11.0"></property>
    </properties>
  </testcase>
  <error type="Error">1 | export const doSomething = () =&gt; {
2 |   throw new Error("something");
            ^
Error: something
  at doSomething (base/node_client/something.js:2:9)
  at base/node_client/error_in_source_function.spec.js:3:1
  at async executeUsingDynamicImport (@jsenv/core/packages/related/test/src/runtime_node/execute_using_dynamic_import.js:71:23)
  at async @jsenv/core/packages/related/test/src/runtime_node/node_child_process_controlled.mjs:122:21</error>
</testsuite>