<!--?xml version="1.0" encoding="UTF-8"?-->
<testsuite time="[time]" timestamp="[timestamp]" tests="2" skipped="0" failures="2">
  <testcase file="error_in_test_function.spec.js" name="worker_thread" time="[time]" timestamp="[timestamp]" tests="1" errors="1">
    <properties>
      <property name="runtimeName" value="node_worker_thread"></property>
      <property name="runtimeVersion" value="22.11.0"></property>
    </properties>
  </testcase>
  <error type="Error">1 | const getCircle = () =&gt; {
2 |   throw new Error("circle");
            ^
Error: circle
  at getCircle (base/node_client/error_in_test_function.spec.js:2:9)
  at base/node_client/error_in_test_function.spec.js:5:1</error>
  <testcase file="error_in_test_function.spec.js" name="child_process" time="[time]" timestamp="[timestamp]" tests="1" errors="1">
    <properties>
      <property name="runtimeName" value="node_child_process"></property>
      <property name="runtimeVersion" value="22.11.0"></property>
    </properties>
  </testcase>
  <error type="Error">1 | const getCircle = () =&gt; {
2 |   throw new Error("circle");
            ^
Error: circle
  at getCircle (base/node_client/error_in_test_function.spec.js:2:9)
  at base/node_client/error_in_test_function.spec.js:5:1</error>
</testsuite>